2022-08-10 14:28:38,686 the exceution will be start from here
2022-08-10 14:28:39,134 True
2022-08-10 14:28:39,146 query completed
2022-08-10 14:28:44,695 Table Created!!
2022-08-10 14:28:49,039 data inserted!!
2022-08-10 14:28:49,707 error has occured
2022-08-10 14:28:49,708 Cursor is not connected
Traceback (most recent call last):
  File "C:\Users\Admin\AppData\Local\Temp/ipykernel_12820/1067763790.py", line 28, in dump_into_mySQL
    cursor.execute("INSERT INTO student_id1 values ({values})".format(values=(list_)))
  File "C:\ProgramData\Anaconda3\lib\site-packages\mysql\connector\cursor.py", line 536, in execute
    raise errors.ProgrammingError("Cursor is not connected")
mysql.connector.errors.ProgrammingError: Cursor is not connected
2022-08-10 14:41:59,668 the exceution will be start from here
2022-08-10 14:42:00,084 True
2022-08-10 14:42:00,085 query completed
2022-08-10 14:42:01,552 Table Created!!
2022-08-10 14:42:02,028 error has occured
2022-08-10 14:42:02,029 1146 (42S02): Table 'wafer_project.student_id1' doesn't exist
Traceback (most recent call last):
  File "C:\Users\Admin\AppData\Local\Temp/ipykernel_12820/1944989908.py", line 29, in dump_into_mySQL
    cursor.execute("INSERT INTO student_id1 values ({values})".format(values=(list_)))
  File "C:\ProgramData\Anaconda3\lib\site-packages\mysql\connector\cursor.py", line 572, in execute
    self._handle_result(self._connection.cmd_query(stmt))
  File "C:\ProgramData\Anaconda3\lib\site-packages\mysql\connector\connection.py", line 922, in cmd_query
    result = self._handle_result(self._send_cmd(ServerCmd.QUERY, query))
  File "C:\ProgramData\Anaconda3\lib\site-packages\mysql\connector\connection.py", line 732, in _handle_result
    raise errors.get_exception(packet)
mysql.connector.errors.ProgrammingError: 1146 (42S02): Table 'wafer_project.student_id1' doesn't exist
2022-08-10 14:45:30,184 the exceution will be start from here
2022-08-10 14:45:30,628 True
2022-08-10 14:45:30,630 query completed
2022-08-10 14:45:33,205 Table Created!!
2022-08-10 14:45:35,136 data inserted!!
2022-08-10 14:45:36,279 error has occured
2022-08-10 14:45:36,280 MySQL Connection not available.
Traceback (most recent call last):
  File "C:\Users\Admin\AppData\Local\Temp/ipykernel_12820/762084481.py", line 22, in dump_into_mySQL
    cursor =mydb.cursor()
  File "C:\ProgramData\Anaconda3\lib\site-packages\mysql\connector\connection.py", line 1280, in cursor
    raise errors.OperationalError("MySQL Connection not available.")
mysql.connector.errors.OperationalError: MySQL Connection not available.
2022-08-10 14:51:35,341 the exceution will be start from here
2022-08-10 14:51:35,526 True
2022-08-10 14:51:35,527 query completed
2022-08-10 14:51:38,032 Table Created!!
2022-08-10 14:51:38,202 True
2022-08-10 14:51:38,203 query completed
2022-08-10 14:51:39,956 data inserted!!
2022-08-10 14:51:40,197 True
2022-08-10 14:51:40,198 query completed
2022-08-10 14:51:41,344 data inserted!!
2022-08-10 14:51:41,541 True
2022-08-10 14:51:41,542 query completed
2022-08-10 14:51:42,881 data inserted!!
2022-08-10 14:51:43,140 True
2022-08-10 14:51:43,141 query completed
2022-08-10 14:51:43,481 data inserted!!
2022-08-10 14:51:43,688 True
2022-08-10 14:51:43,689 query completed
2022-08-10 14:51:43,709 data inserted!!
2022-08-10 14:51:43,767 True
2022-08-10 14:51:43,769 query completed
2022-08-10 14:51:44,263 data inserted!!
2022-08-10 14:51:44,721 True
2022-08-10 14:51:44,808 query completed
2022-08-10 14:51:45,265 data inserted!!
2022-08-10 14:51:45,511 True
2022-08-10 14:51:45,513 query completed
2022-08-10 14:51:46,477 data inserted!!
2022-08-10 14:51:46,921 True
2022-08-10 14:51:46,922 query completed
2022-08-10 14:51:47,218 data inserted!!
